Workbook

Sheet papertargets3
A1: Target | B1: manipulation | C1: Product | D1: DOI | E1: in_genemapping | F1: Predicted by ET-OptME | G1: comments
A2: dld | B2: Overexpression | C2: L-lysine | D2: 10.1002/biot.201000307 | E2: TRUE | F2: =IFERROR(VLOOKUP(A2,Sheet1!A:A,1,0),0) -> 0 | G2: LDH_D2: lac__D_c + q8_c --> pyr_c + q8h2_c
A3: pyc | B3: Overexpression | C3: L-lysine | D3: 10.1128/aem.01942-09 | E3: TRUE(自动匹配失败，手动匹配成功） | F3: =IFERROR(VLOOKUP(A3,Sheet1!A:A,1,0),0) -> pyc | G3: Overexpression of pyruvate carboxylase to increase lysine production | Citation: The overexpression of these genes using again the sod promoter resulted in growth-associated production of lysine with lactate as sole carbon source with a carbon yield of 9% and a yield of 15% during growth on a lactate-glucose mixture. | Overexpression of pyruvate carboxylase from Corynebacterium glutamicum to enhance succinic acid production | Citation: Best succinic acid production was observed with expression of heterologous pyruvate carboxylase (pyc; C. glutamicum), reaching a final product concentration of up to 26.8 g L -1 and a cell-specific productivity of up to 0.31 g g -1 h -1 (E. coli wt scr/pyc_Cg). | Overexpression of pyruvate carboxylase gene pyc to improve anaplerosis. | Citation: Overexpression of glyceraldehyde 3-phosphate dehydrogenase gene gapA, pyruvate carboxylase gene pyc, and argB A49V/M54V encoding a variant of N-N-acetyl-glutamate kinase that is not feedback-inhibited by L-arginine has previously been shown to improve anaplerosis and glycolytic flux in putrescine producing C. glutamicum strains and in consequence improved the specific and volumetric productivities for putrescine production. | Improved anaplerotic reaction | Citation: Threonine formation was decreased by the introduction of a hom V58A mutation in homoserine dehydrogenase, whereas the anaplerotic reaction was improved by the deletion of the gene encoding PEP carboxykinase and introduction of a variant (pyc P458S ) of the pyruvate carboxylase gene. | Introduction of pyruvate carboxylase (Pyc) from C. glutamicum to convert pyruvate into OAA. | Citation: we integrated one copy of Ptrc-pyc P458S, a feedback-insensitive pyruvate carboxylase variant. | The pyc gene from C. glutamicum was selected to catalyze the carboxylation of pyruvate to oxaloacetate. | Citation: The pyc gene from C. glutamicum was selected, which has been reported with high activity to catalyze the carboxylation of pyruvate to oxaloacetate. | Site-directed modification of the pyc gene to relieve the PCx inhibition by L-aspartate and increase the PCx activity. | Citation: To increase the flux from pyruvate to OAA, we site-directed modified the pyc gene in order to relieve the PCx inhibition by L-aspartate and increase the PCx activity. | Glycolysis and anaplerosis were enhanced by plasmid-borne overexpression of the genes for glyceraldehyde 3-phosphate dehydrogenase and pyruvate carboxylase. | Citation: Glycolysis and anaplerosis were enhanced by plasmid-borne overexpression of the genes for glyceraldehyde 3-phosphate dehydrogenase and pyruvate carboxylase. | The pyc mutation (P458S) remains unclear regarding effects on the phenotype of the wild-type strain and on the catalytic properties of the pyc product. | Citation: The pyc mutation (P458S) remains unclear regarding effects on the phenotype of the wild-type strain and on the catalytic properties of the pyc product. | The pyc458 mutation was introduced into strain AHD-2 by allelic replacement using plasmid pCpyc458, resulting in the creation of strain AHP-3 that carried the pyc mutation in addition to the hom and lysC mutations in its genome. | Citation: The pyc mutation was thus introduced into strain AHD-2 by allelic replacement using plasmid pCpyc458, resulting in the creation of strain AHP-3 that carried the pyc mutation in addition to the hom and lysC mutations in its genome. | Chromosomal reintroduction of this pyc mutation in a wild-type genetic background had no positive effect on L-lysine production. | Citation: Chromosomal reintroduction of this pyc mutation in a wild-type genetic background had no positive effect on L-lysine production, while this mutation was beneficial for L-lysine production when introduced into an HD-deficient L-lysine overproducing C. glutamicum host. | Point mutations in lysC, hom, and pyc genes for L-lysine production | Citation: The genetically defined L-lysine-producing strain DM1729, which differs from C. glutamicum WT by point mutations in the aspartokinase gene lysC, the homoserine dehydrogenase gene hom, and the pyruvate carboxylase gene pyc (Georgi et al. 2005), was transformed with the following plasmid combinations pVWEx1 and pEKEx3, pVWEx1-araBAD and pEKEx3, pVWEx1 and pEKEx3-xylA, as well as pVWEx1-araBAD and pEKEx3-xylA. | Overexpression of pyruvate carboxylase to increase succinate production | Citation: We adopted a similar strategy to generate the PYC expression plasmid. | The pyc gene encoding PYC was overexpressed by replacing the pyc promoter with the tuf promoter. | Citation: For succinic acid production, genes involved in production of lactic acid (ldhA) and acetic acid (pta, ack, pqo, cat) were deleted, while the pyc gene encoding PYC (Fig. 1) was overexpressed by replacing the pyc promoter with the tuf promoter. | Overexpression of pyc to increase the pyruvate to oxaloacetate flux | Citation: Moreover, we overexpressed the pyc gene to increase the pyruvate to oxaloacetate flux, as previously described. | The pyc458 mutation in the pyruvate carboxylase gene was defined as a positive mutation for improved production. | Citation: Three specific mutations, pyc458 (P458S) in the anaplerotic pathway, gnd361 (S361F) in the pentose phosphate pathway, and mqo224 (W224opal) in the TCA cycle, were defined as positive mutations for improved production. | Double disruption of dtsR1 and pyc induced efficient L-glutamate overproduction in C. glutamicum. | Citation: Double disruption of dtsR1 (encoding a subunit of acetyl-CoA carboxylase complex) and pyc (encoding pyruvate carboxylase) caused efficient overproduction of L-glutamate in C. glutamicum; production was much higher than that of the wild-type strain and dtsR1 strain under glutamate-inducing conditions. | Chromosomal integration of the pyruvate carboxylase gene pyc to increase oxaloacetate provision | Citation: To enhance C 3 -C 4 carboxylation efficiency, chromosomal integration of the pyruvate carboxylase gene pyc resulted in strain NC-4. | Deletion of pyc gene to regulate the TCA cycle supplementation pathway and increase the pyruvate availability. | Citation: In this study, the p pyc gene (encoding PC) was deleted to regulate the TCA cycle supplementation pathway and increase the pyruvate availability. | Point mutation of pyc to increase methionine precursor supply. | Citation: followed by point mutations of lysC (C932T) and pyc (G1A, C1372T) to increase methionine precursor supply. | The pyc gene was deleted to increase the precursor of GABA, L-glutamate. | Citation: To improve GABA production in recombinant C. glutamicum, the odhA gene and pyc gene were individually deleted to increase the precursor of GABA, L-glutamate. | The pyc gene coding for pyruvate carboxylase was overexpressed to increase the biosynthetic pool of oxaloacetate. | Citation: Moreover, the pyc gene coding for pyruvate carboxylase and the ppc gene coding for phosphoenolpyruvate carboxylase were overexpressed to increase the biosynthetic pool of oxaloacetate. | Mutated pyruvate carboxylase for lysine production | Citation: A basic lysine-producing strain derived from C. glutamicum ATCC 13032 was constructed based on the metabolic engineering strategies described in the literature (Becker et al. 2011), which contained mutated hom T176C (homoserine dehydrogenase) and pyc C1372T (pyruvate carboxylase) in the chromosome, pck (PEP carboxykinase) deletion and the additional copy of the mutated pyc C1372T and dapB (dihydrodipicolinate reductase) in the pck locus. | Overexpression of the PYC gene in a lysine-producing strain of Corynebacterium glutamicum resulted in approximately 50% higher lysine accumulation | Citation: For example, overexpression of the PYC gene in a lysine-producing strain of Corynebacterium glutamicum resulted in approximately 50% higher lysine accumulation in the culture supernatant whereas inactivation of the PYC gene led to a decrease by 60% (Peters-Wendisch et al. 2001). | Simultaneous overexpression of pyruvate carboxylase and aspartate kinase genes in C. glutamicum to increase lysine productivity. | Citation: The simultaneous amplification of the activities of the two enzymes yielded more than 250% increase of the lysine specific productivity in lactate minimal medium without affecting the growth rate or final cell density of the culture. | Overexpression of pyc P458S to increase L-homoserine production. | Citation: To increase the production of L-aspartate family amino acids, pyc P458S (encoding a feedback-insensitive pyruvate carboxylase) and the aspC gene derived from E. coli K12-MG1655 were overexpressed in strain Cg03. | Overexpression of pyc to increase oxaloacetate supply for 5-ALA production | Citation: To explore whether oxaloacetate supply contributes to 5-ALA production, pyc (encoding pyruvate carboxylase) and ppc (encoding phosphoenolpyruvate carboxylase) were overexpressed via the Ptuf promoter, resulting in strain A5 and A6. | Enhancing the carbon flux to succinate | Citation: The native pyc and ppc gene were thus overexpressed in C. glutamicum K1 to shift the carbon flux from the C3 pathway to the C4 pathway, enhancing succinate accumulation. | Overexpression of pyruvate carboxylase and PEP carboxylase is an effective strategy to enhance carbon flux towards OAA. | Citation: Therefore, the gene pck encoding PEP carboxykinase was deleted from the LYS-1 genome and simultaneously overexpressed ppc and pyc under the control of the strong promoter Ptrc. | Overexpression of pyruvate carboxylase to improve itaconate production | Citation: the highest production of itaconate was achieved from CG-Pyc overexpression in the Δicd strain coupled with AT-CAD, EC-AcnB, and EC-GltA overexpression, reaching approximately 3.2 g/L in 24 h. | Overexpression of pyruvate carboxylase to enhance lysine production. | Citation: Overexpression of the genes fbp and gapX in C. glutamicum was achieved by cloning the open reading frame (ORF) of the mentioned genes under the control of the strong constitutive promoter of the sod gene, encoding superoxide dismutase (NCgl2826). | The point-mutation in the pyruvate carboxylase (p(pyc) gene enhances the supply of oxaloacetate needed as a precursor for L-lysine production. | Citation: The point-mutation in the pyruvate carboxylase (p(pyc) gene enhances the supply of oxaloacetate needed as a precursor for L-lysine production. | Overexpression of pyc to improve succinate production. | Citation: Overexpression of pyc by plasmid pT184pyc in mutant ZJG13 was also found to be effective in resuming cell growth and glucose consumption. | Nucleotide exchange in the pyc gene encoding pyruvate carboxylase resulting in the amino acid exchange P485S. | Citation: LYS-8 LYS-7+nucleotide exchange in the pyc gene, encoding pyruvate carboxylase resulting in the amino acid exchange P485S. | Overexpression of pyc by the sod promoter. | Citation: LYS-9 LYS-8+over expression of pyc by the sod promoter. | Deletion of the pyc gene, encoding pyruvate carboxylase | Citation: C. glutamicum ΔpΔppc ΔpΔpyc C. glutamicum ΔpΔppc with additional deletion of the pyc gene, encoding pyruvate carboxylase This work | Replacement of wild-type pyc gene with pyc P458S to improve conversion of pyruvate to oxaloacetate | Citation: Because increased metabolic flux from pyruvate to OAA was shown to be a key factor of high succinate production (Inui et al., 2004), the wild-type pyc gene of the S003 strain was replaced with pyc P458S, which was reported to be beneficial for the reaction converting pyruvate to oxaloacetate (Ikeda et al., 2006), resulting in the S006 strain. | Overexpression of pyruvate carboxylase to improve oxaloacetate supply | Citation: Thus, ppc and pyc genes that encode phosphoenolpyruvate carboxylase and pyruvate carboxylase, respectively, were chromosomally overexpressed by changing their promoters with stronger ones: Ptuf promoter for ppc, and PsPsod promoter for pyc. | Overexpression of pyruvate carboxylase to improve lysine production | Citation: overexpressing key enzymes of pyruvate carboxylase (encoded by mutated pyc, c, PycAP AP458S ) | Repression of pyruvate carboxylase to redirect carbon flux towards squalene production | Citation: Repressing pyc encoding for pyruvate carboxylase in the L-lysine producer (DM1919) and its derivatives | Overexpression of pyc to convert pyruvate to OAA, enhancing β-alanine production. | Citation: To further augment OAA availability, we introduced the pyc gene from C. glutamicum, which encodes pyruvate carboxylase (PYC) capable of converting pyruvate to OAA. | Pyruvate carboxylase from C. glutamicum (PYC) was employed to allocate flux into the TCA cycle with simultaneous CO2 utilization. | Citation: To adjust this inadequate overflow in glycolysis that limited GA synthesis, phosphoenolpyruvate carboxylase (PPC) and pyruvate carboxylase from C. glutamicum (PYC) were employed to allocate flux into the TCA cycle with simultaneous CO2 utilization. | Pyruvate carboxylase encoded by pyc in C. glutamicum catalyzes the conversion of PYR to OAA | Citation: Phosphoenolpyruvate carboxylase encoded by ppc in E. coli catalyzes the conversion of PEP to OAA, and pyruvate carboxylase encoded by pyc in C. glutamicum catalyzes the conversion of PYR to OAA. | Introduction of pyc from C. glutamicum to convert Pyr to OAA | Citation: In this study, pyc from C. glutamicum was introduced into ALA8, and the resultant strain ALA10 produced 4.07 g/L β-alanine. | Overexpression to increase the availability of homoserine for the synthetic pathway. | Citation: A feedback-insensitive pyruvate carboxylase from C. glutamicum (p(pyc P458S ) and a bifunctional aspartokinase/homoserine dehydrogenase (thrA G433R ) from E. coli were overexpressed to increase the availability of homoserine for the synthetic pathway. | The pyc gene was deleted to create a strain suitable for screening a mutant library for improved PCx variants. | Citation: Therefore, we used strain DM1868, which is an ATCC13032 derivative encoding the feedback-resistant aspartate kinase variant LysC T311I (Table S2). | The pyc gene was overexpressed to increase lysine production. | Citation: IPTG-induced overexpression of pyc via plasmid pAN6-p-pyc in strains DM1868 and DM1868ΔpΔpyc caused an increase of the lysine titer by 63% compared to strain DM1868/pAN6. | The pyc P458S variant was introduced to enable a 7% increase in lysine production. | Citation: The pyc P458S variant was reported to enable a 7% increase in lysine production compared to wild-type pyc in a strain carrying additionally the lysC T311I mutation. | The PCxT T132A variant was identified to allow 19% increased lysine titers. | Citation: The best strain was RC7, which carried a single amino acid exchange (PCxT xT132A ) and formed 19% more lysine (45.7 ± 1.7 mM) than the reference strain (38.4 ± 2.2 mM). | The PCxT T343A, I1012S variant was identified to allow 9% increased lysine titers. | Citation: Second best was strain RC4 carrying two amino acid exchanges (PCxT xT343A, I1012S ) with a 9% higher lysine titer (41.8 ± 1.0 mM). | Introduction of a mutation in pyruvate carboxylase gene to increase enzyme activity | Citation: a mutation in a gene encoding pyruvate carboxylase (p(pyc) resulting in a substitution of proline at position 328 by serine to increase enzyme activity. | Overexpression of pyruvate carboxylase gene by exchanging the native promoter with the tuf promoter | Citation: we ensured overexpression of the pyc gene by exchanging the native pyc promoter with the tuf promoter. | Deletion of pyc to reduce succinate production | Citation: Therefore, ppc and pyc were individually deleted in CGR7, yielding CGR9 and CGR10, respectively. | The native promoter of the pyc gene was replaced with the H36 promoter. | Citation: The GA9 strain was further engineered by replacing the promoter of the pyc gene with the H36 promoter to make the GA10 strain. | Overexpression of pyc gene from C. glutamicum to enhance succinate production. | Citation: Based on our hypothesis, overexpression of pyc from C. glutamicum would be most effective in converting pyruvate to the succinate precursor 4-carbon metabolites. | Overproduction of pyruvate carboxylase and PEP carboxylase to improve succinate production | Citation: The combined overproduction of PEPCx (encoded by the ppc gene) with PCxP458S was expected to further stimulate the synthesis from oxaloacetate and therefore the expression plasmid pAN6-pycPcP458S ppc was constructed. | Deletion of the pyruvate carboxylase gene to improve L-valine production. | Citation: Deletion of the pyruvate: quinone oxidoreductase, phosphoglucose isomerase, and pyruvate carboxylase genes (p(pqo , pgi, and pyc, respectively) in C. glutamicum -aceE(pJC4ilvBNCE) further improved L-valine production (5). | Chromosomal integration of the pyc P458S gene to enhance pyruvate carboxylation | Citation: Alternatively, the pyc P458S gene under the control of the strong constitutive promoter of the tuf gene was chromosomally integrated into the deleted pta-ack region of the BOL-1 strain, resulting in strain C. glutamicum cat p pqo p pta-ack::P tuf pyc P458S ldhA (BOL-2). | P458S mutation in the pyc gene, encoding pyruvate carboxylase, and overexpression by sod | Citation: sodp pyc(P(P458S) P458S mutation in the pyc gene, encoding pyruvate carboxylase, and overexpression by sod | Introduction of pyruvate carboxylase to direct pyruvate to oxaloacetate. | Citation: introducing the pyruvate carboxylase gene into the engineered strain to direct pyruvate to the oxaloacetate rather than the acetyl-CoA; | The pyc gene was inactivated to study its role in succinate production. | Citation: A pyruvate carboxylase (pyc) mutant exhibited similar behavior to that of the wild type. | Overexpression of the pyc gene to study its effect on succinate formation. | Citation: We also studied succinate production by a wild-type strain overexpressing the pyc genes (WT-pCRA716) and compared it to production by an ldhA-deficient mutant overexpressing the same pyc gene (ldhA-pCRA716). | Overexpression of pyc gene to improve succinate yield by carboxylating pyruvate to oxaloacetate | Citation: In addition, pyc gene (coding a pyruvate carboxylase originated from Corynebacterium glutamicum ATCC 13032 [35]) was overexpressed to achieve higher yields of succinate by efficiently carboxylazing of pyruvate to oxaloacetate in this trimutant background. | As replacement for the anaplerotic reaction of Ppc the pyruvate carboxylase gene (p(pyc) of Corynebacterium glutamicum was inserted into the chromosomal malEG locus under control of the tac-promotor. | Citation: As replacement for the anaplerotic reaction of Ppc the pyruvate carboxylase gene (p(pyc) of Corynebacterium glutamicum was inserted into the chromosomal malEG locus under control of the tac-promotor. | Introduction to enhance glucose consumption and succinate yield | Citation: In addition, removing byproduct formation through inactivating acetate formation genes ackA-pta and heterogenously expressing pyc (encoding pyruvate carboxylase) from C. glutamicum led to improved succinate yield to 1.4 mol/mol glucose. | Repression of pyc gene to investigate the performance of the CRISPRi | Citation: First, a Pyc-targeting recombinant (Wt pCoryne-dCas9 psgRNA-pyc-r) was constructed to investigate the performance of the CRISPRi. | Deletion of the pyc gene in this strain increased noreugenin synthesis and enabled accumulation of 5.63 mg/L (0.029 mM) noreugenin within 72 h. | Citation: Deletion of the pyc gene in this strain increased noreugenin synthesis and enabled accumulation of 5.63 mg/L (0.029 mM) noreugenin within 72 h. | Deletion of pyc to reduce succinate accumulation and improve acetoin production | Citation: In this study, we deleted the ppc and pyc genes in CGR6 using a markerless two-step recombination method (double crossover) [35], resulting in the strains CGS1 and CGS2, respectively. | Overexpression of pyruvate carboxylase to improve succinate production | Citation: It has been proved that overexpression of pyruvate carboxylase (p(pyc), citrate synthase (g(gltA), and succinate exporter (sucE) could efficiently improve succinate production in C. glutamicum. | Overexpression of pyc gene from Corynebacterium glutamicum to enhance malic acid production | Citation: Then pyc gene from Coryenbacterium glutamicus and pck gene from Actinobacillus succinogenes were overexpressed in E21 separately. | The pyc disruptant showed increased lactate production in addition to glutamate production under biotin-limited conditions | Citation: The pyc disruptant showed increased lactate production in addition to glutamate production under biotin-limited conditions (Fig. 1D), possibly because of pyruvate accumulation. | Overexpression of pyruvate carboxylase to enhance malonic acid production | Citation: In this study, a recombinant Escherichia coli strain BL21(TPP) was constructed to synthesize malonate through overexpressing six genes of ppc, aspC, panD, pa0132, yneI and pyc. | Knockout of genes to reduce by-product accumulation and increase pyruvate production | Citation: 其次，对丙酮酸上游间接代谢副产物，如琥珀酸，涉及的相关基因，如磷酸烯醇式丙酮酸羧化酶(p(ppc)和丙酮酸羧化酶(p(pyc)，进行组合敲除，获得工程菌株 C . glutamicum K007 (K006ΔpΔppc) 、 C . glutamicum K008 (K006ΔpΔpyc)和 C . glutamicum K009 (K006ΔpΔppcΔpΔpyc)，丙酮酸产量分别提高到了 11.3 、 11.6 和 9.4 g/L，琥珀酸积累量分别下降了 66.20% 、 43.66%和 71.83% (图 3D)。 | Inactivation of pyruvate carboxylase to improve phenylalanine production | Citation: Thus, the effects of deletion of the pyc, ppc, and pyk genes encoding pyruvate carboxylase (PC), phosphoenolpyruvate carboxylase (PEPC), and pyruvate kinase (PYK), respectively, and the reduction of the citrate synthase (CS) activity, on the phenylalanine production were investigated (Fig. 4A). | Overexpression of the pyc gene slightly increased putrescine production | Citation: As shown in Table 2, overexpression of the native pyc gene slightly increased putrescine production, while overexpression of the mutated pyc458 gene markedly increased putrescine production by 16% to 133.51 ± 7.20 mM. | Overexpression of the mutated pyc458 gene markedly increased putrescine production | Citation: As shown in Table 2, overexpression of the native pyc gene slightly increased putrescine production, while overexpression of the mutated pyc458 gene markedly increased putrescine production by 16% to 133.51 ± 7.20 mM. | Expression of pyruvate carboxylase to increase oxaloacetate accumulation | Citation: By expressing a heterologous gene, pyc, in the engineered E. coli, the accumulation of intracellular oxaloacetate remarkably improved. | Overexpression of pyruvate carboxylase to enhance anaplerosis | Citation: Based on these simulations, enhancing glycolysis and anaplerosis by plasmid-borne overexpression of the genes for glyceraldehyde 3-phosphate dehydrogenase and pyruvate carboxylase as well as reducing 2-oxoglutarate dehydrogenase activity were chosen as targets for metabolic engineering. | Overexpression of pyc P458S to improve pyruvate carboxylase activity | Citation: To investigate the impact on DPA production, the genes lysC T311I, pyc P458S, ppc, or ppc and pyc P458S were overexpressed from an IPTG-inducible plasmid in strain Dpa1 that already carries chromosomal copies of lysC T311I and pyc P458S.
A4: mtlR | B4: Inactivation | C4: L-lysine | D4: 10.1023/A:1020353124066 | E4: FALSE | F4: =IFERROR(VLOOKUP(A4,Sheet1!A:A,1,0),0) -> 0 | G4: Deletion of mtlR enables L-ornithine accumulation on mannitol | Citation: Deletion of mtlR enables L-ornithine accumulation on mannitol. | Deletion of the mannitol repressor MtlR enables the transcription of mtlT and mtlD and subsequent mannitol utilization | Citation: Deletion of the mtlR gene enables the transcription of mtlT and mtlD and subsequent mannitol utilization (Peng et al., 2011). | enables the transcription of mtlT and mtlD and subsequent Mannitol utilization | Citation: It was recently established by deletion of the repressor AtlR (also known as MtlR) in C. glutamicum LYS-12, which additionally contained twelve genome-based modifications for L-lysine hyperproduction from glucose (shown in blue in the figure) (Becker et al., 2011). | Deletion of mtlR; overexpression of mtlD and pfkB | Citation: Deletion of mtlR; over expression of mtlD and pfkB
A5: ack | B5: Inactivation | C5: L-lysine | D5: 10.3389/fbioe.2021.669093 | E5: FALSE | F5: =IFERROR(VLOOKUP(A5,Sheet1!A:A,1,0),0) -> 0 | G5: Deletion of ack to reduce acetyl-CoA to acetic acid flux | Citation: The ack (acetate kinase) was substituted by araE (pentose transporter) to reduce the flux of acetyl-CoA to acetic acid. | For succinic acid production, genes involved in production of lactic acid (ldhA) and acetic acid (pta, ack, pqo, cat) were deleted. | Citation: For succinic acid production, genes involved in production of lactic acid (ldhA) and acetic acid (pta, ack, pqo, cat) were deleted, while the pyc gene encoding PYC (Fig. 1) was overexpressed by replacing the pyc promoter with the tuf promoter. | Deletion of acetate kinase gene to minimize acetate production | Citation: menaquinone oxidoreductase (p(pqo), acetyl-CoA transferase (cat), acetate kinase (ack), and phosphotransacetylase (p(pta) to minimize acetate production | Deletion of ack to reduce acetate production | Citation: To reduce lactate and acetate production, ldh, pta and ack were deleted together in C. glutamicum ATCC 13032, yielding CGF0. | Deleted ack and pta to prevent unnecessary accumulation of acetate | Citation: To prevent unnecessary accumulation of acetate during the shikimate production process, we removed acetate kinase (Ack) and phosphotransacetylase (Pta) involved in acetate accumulation.
A6: pta | B6: Inactivation | C6: L-lysine | D6: 10.1016/j.biortech.2017.05.135 | E6: TRUE | F6: =IFERROR(VLOOKUP(A6,Sheet1!A:A,1,0),0) -> pta | G6: PTAr: accoa_c + pi_c <=> actp_c + coa_c, PTA2
A7: dapE | B7: Overexpression | C7: L-lysine | D7: 10.1016/S0168-1656(03)00156-1 | E7: TRUE | F7: =IFERROR(VLOOKUP(A7,Sheet1!A:A,1,0),0) -> dapE | G7: SDPDS: h2o_c + sl26da_c --> 26dap_LL_c + succ_c
A8: thrC | B8: Inactivation | C8: L-lysine | D8: 10.1016/S1389-1723(99)80196-0 | E8: TRUE | F8: =IFERROR(VLOOKUP(A8,Sheet1!A:A,1,0),0) -> thrC | G8: THRS: h2o_c + phom_c --> pi_c + thr__L_c
A9: ilvC | B9: Inactivation | C9: L-lysine | D9: 10.1016/j.plasmid.2014.07.005 | E9: TRUE | F9: =IFERROR(VLOOKUP(A9,Sheet1!A:A,1,0),0) -> ilvC | G9: KARA1: 23dhmb_c + nadp_c <=> alac__S_c + h_c + nadph_c, KARA2: 2ahbut_c + h_c + nadph_c <=> 23dhmp_c + nadp_c, DPR: 2dhp_c + h_c + nadph_c --> nadp_c + pant__R_c
A10: ilvE | B10: Inactivation | C10: L-lysine | D10: 10.1016/j.plasmid.2014.07.005 | E10: TRUE | F10: =IFERROR(VLOOKUP(A10,Sheet1!A:A,1,0),0) -> ilvE | G10: PHETA1: glu__L_c + phpyr_c <=> akg_c + phe__L_c, LEUTAi: 4mop_c + glu__L_c <=> akg_c + leu__L_c, ILETA: 3mop_c + glu__L_c <=> akg_c + ile__L_c, VALTA: 3mob_c + glu__L_c --> akg_c + val__L_c, TYRTA: 34hpp_c + glu__L_c <=> akg_c + tyr__L_c
A11: pgi | B11: Overexpression | C11: L-lysine | D11: 10.3389/fmicb.2021.718511 | E11: TRUE | F11: =IFERROR(VLOOKUP(A11,Sheet1!A:A,1,0),0) -> 0 | G11: PGI: g6p_c <=> f6p_c
A12: leuA | B12: Inactivation | C12: L-lysine | D12: 10.1007/s00253-007-0916-x | E12: TRUE | F12: =IFERROR(VLOOKUP(A12,Sheet1!A:A,1,0),0) -> leuA | G12: IPPS: 3mob_c + accoa_c + h2o_c --> 3c3hmp_c + coa_c + h_c
A13: lysC | B13: Dynamic regulation | C13: L-lysine | D13: 10.3390/microorganisms12030606 | E13: TRUE | F13: =IFERROR(VLOOKUP(A13,Sheet1!A:A,1,0),0) -> lysC | G13: ASPK: asp__L_c + atp_c <=> 4pasp_c + adp_c
A14: lpdA | B14: Overexpression | C14: L-lysine | D14: 10.1002/bit.27485 | E14: FALSE | F14: =IFERROR(VLOOKUP(A14,Sheet1!A:A,1,0),0) -> 0 | G14: Not found in genemapping or cg_modifications
A15: acs | B15: Overexpression | C15: L-lysine | D15: 10.1002/bit.27485 | E15: TRUE | F15: =IFERROR(VLOOKUP(A15,Sheet1!A:A,1,0),0) -> 0 | G15: ACS, ACCOAL
... A45: ilvA | B45: Overexpression | C45: L-lysine | D45: 10.1016/S1389-1723(99)80196-0 | E45: TRUE | F45: =IFERROR(VLOOKUP(A45,Sheet1!A:A,1,0),0) -> 0 | G45: THRD_L: thr__L_c --> 2obut_c + nh4_c
A46: ddh | B46: Introduction | C46: L-lysine | D46: 10.1016/j.ymben.2011.01.003 | E46: TRUE(自动匹配失败，手动匹配成功） | F46: =IFERROR(VLOOKUP(A46,Sheet1!A:A,1,0),0) -> ddh | G46: The ddh gene was integrated into the chromosome of strain XQ60 at the locus of isocitrate lyase regulator gene (iclR). | Citation: Furthermore, the ddh gene was integrated into the chromosome of strain XQ60 at the locus of isocitrate lyase regulator gene (iclR), which resulted in strain XQ64 with the iclR gene disrupted. | Overexpression of diaminopimelate dehydrogenase DdH from Corynebacterium glutamicum to strengthen Lys synthetic pathways | Citation: Firstly, exogenous addition of Lys was proven to be favorable for bacitracin production, and the strain LYS2 was attained through strengthening Lys synthetic pathways via overexpressing diaminopimelate decarboxylase LysA from B. licheniformis and diaminopimelate dehydrogenase DdH from Corynebacterium glutamicum, and the bacitracin produced by LYS2 was increased to 838.53 U/mL by 10.85%, compared with that of DW2 (756.45 U/mL). | Over-expression of ddh gene to increase flux in aminotransferase pathway. | Citation: The ddh gene was over expressed by insertion of the ddh cassette into C. glutamicum Lys5-6 chromosome at avtA gene locus resulting in C. glutamicum Lys5-7 to increase the flux in aminotransferase pathway. | Overexpression of diaminopimelate dehydrogenase for lysine production | Citation: Besides, lysC C932T , ddh and lysA were overexpressed on the plasmid pXMJ19 and the resulted strain LYS-1 served as the platform to evaluate the effect of promoter engineering. | The deletion of ddh gene encoding diaminopimelate dehydrogenase of Lys synthesis pathway could increase 4-HIL titer without a significant decrease of cell growth and Lys content. | Citation: Previous studies have shown that the deletion of ddh gene encoding diaminopimelate dehydrogenase of Lys synthesis pathway could increase 4-HIL titer without a significant decrease of cell growth and Lys content. | Heterologous gene expression | Citation: In the case of the lysine synthesis pathway, we have engineered eight genomic locations to exchange native promoters for synthetic constitutive promoter [BBa_J23100; lysCf Cfbr (D-lysC-F, D-lysC-R, P-lysC-F, P-lysC-R), dapA (P-dapA-F, P-dapA-R), dapB (P-dapB-F, P-dapB-R), and lysA (P-lysA-F, P-lysA-R)]; heterologous gene expression [ddh fromCorynebacterium glutamicum (S-ddh-F, S-ddh-R, P-ddh-F, P-ddh-R)]; and knockout [metL (D-metL-F, D-metL-R), thrA (D-thrA-F, D-thrA-R), and iclR (D-iclR-F, D-iclR-R)] using lambda-Red recombination system encoded in pKD46 plasmid. | Heterologous expression of ddh from C. glutamicum increases l-lysine accumulation and improves the productivity of the strain. | Citation: Heterologous expression of ddh not only increases the l-lysine accumulation but also improves the productivity of the strain. | Deletion of ddh improved l-threonine production by 17% | Citation: deletion of ddh improved l-threonine production by 17%, and additional deletion of lysE further improved l-threonine production by 28%; | Deletion of ddh improved l-isoleucine production by 8% and improved cell growth by 21% | Citation: deletion of ddh improved l-isoleucine production by 8% and improved cell growth by 21%, whereas additional deletion of lysE had no further influence on both l-isoleucine production and cell growth; | Enhanced biosynthetic flux via combined amplification of aspartokinase, dihydrodipicolinate reductase, diaminopimelate dehydrogenase and diaminopimelate decarboxylase. | Citation: Substantially re-designing the metabolism yielded superior strains with desirable properties such as (iii) enhanced biosynthetic flux via combined amplification of aspartokinase, dihydrodipicolinate reductase, diaminopimelate dehydrogenase and diaminopimelate decarboxylase. | Additional copy of the ddh gene encoding diaminopimelate dehydrogenase to promote flux increase. | Citation: Based on the prediction by in silico pathway analysis, the dehydrogenase branch was selected as most favorable biosynthetic route for lysine (Melzer et al., 2009). A second copy of the ddh gene encoding diaminopimelate dehydrogenase was introduced to promote flux increase. | Replacement of native ddh gene by ddh_Pt gene to enhance NADH utilization | Citation: Replacement of endogenous DAPDH by PtDAPDH reduced lysine yield by 3.8%, probably due to that the activity of DAPDH in the recombinant strain (323 ± 26 mU/mg for NAD + ) was lower than that in the control strain (1124 ± 123 mU/mg for NADP + , Table 3). | Deleting gene ddh encoding diaminopimelate dehydrogenase to reduce lysine accumulation and increase threonine and isoleucine production. | Citation: Recombinant C. glutamicum producing Thr and Ile with little lysine accumulation was obtained by deleting gene ddh encoding diaminopimelate dehydrogenase and lysE encoding lysine-specific exporter. | Overexpression of lysC Q298G, asd, dapA, and ddh genes to increase lysine production | Citation: E. coli AC01 is a high lysine-producing strain overexpressing four limiting enzymes of lysine synthesis pathway, namely lysC Q298G, asd, dapA, and ddh genes from C. glutamicum encoding aspartate kinase, aspartate-semialdehyde dehydrogenase, dihydrodipicolinate synthase and diaminopimelate dehydrogenase in plasmid. | An additional copy of the ddh gene was integrated to enhance L-lysine production. | Citation: Next, the production of the key precursor, L-lysine, was enhanced by integrating the second copy of ddh encoding diaminopimelate dehydrogenase next to the ddh gene in the genome. | Knockout of diaminopimelate dehydrogenase to increase malonyl-CoA production | Citation: The envelope of Fig. 3 shows the most promising predicted deletion strategies to enhance the malonyl-CoA supply for naringenin production.
A47: mcbR | B47: Inactivation | C47: L-lysine | D47: 10.1016/j.bej.2020.107665 | E47: FALSE | F47: =IFERROR(VLOOKUP(A47,Sheet1!A:A,1,0),0) -> 0 | G47: Deletion of the gene mcbR encoding the regulator McbR to release the transcriptional repression to various genes in the L-methionine biosynthetic pathway | Citation: deletion of the gene mcbR encoding the regulator McbR to release the transcriptional repression to various genes in the L-methionine biosynthetic pathway | mcbR gene overexpression improves acid tolerance by repressing sulfur assimilation and cysteine biosynthesis. | Citation: overexpression of mcbR improved the tolerance of C. glutamicum to low pH. | Repression of mcbR gene to improve cysteine production | Citation: The deletion of aecD alone increased the production for about 2.5-fold (28.7 mg/L), while the combined aecD deletion and mcbR repression using RECRISPR system further increased the production to 3.7-fold (42.8 mg/L), as compared to the wild-type strain. | Deletion of mcbR to improve production of l-cysteine | Citation: McbR encoded by mcbR has been identified as a transcriptional repressor involved in the regulation of biosynthesis of sulfur-containing amino acids in C. glutamicum [24], and the deletion of mcbR also improved the production of l-cysteine up to 1.5-fold. | The mcbR gene was deleted to investigate its regulatory role in the metabolic network of L-methionine and L-cysteine biosynthesis. | Citation: The deletion was introduced into the mcbR gene by gene SOEing (Horton, 1995) as described by Wehmeier et al. (2001). | Deletion of mcbR to construct a strain exhibiting high-level production of L-homoserine. | Citation: In the present study, we deleted thrB, mcbR, and metD to construct a strain exhibiting high-level production of L-homoserine. | Deletion of mcbR to relieve repression of methionine biosynthetic pathway | Citation: The aim of this study was to enhance SAM production in C. glutamicum . C. glutamicum SAM-producing strain HW105 were developed from wild type C. glutamicum ATCC13032 by deleting genes thrB , metB , mcbR and Ncgl2640 , and overexpressing two genes metK and vgb . | Deletion of the McbR gene to improve taurine production, L-cysteine biosynthesis, and sulfur assimilation. | Citation: The next strategy focused on whether the synergistic effect of the combined pathway (consisting of CS, CDO1, and CSAD) could improve taurine production (Figure 1C). The final strategy focused on the effect of deleting the mcbR gene to improve taurine production, L-cysteine biosynthesis, and sulfur assimilation (Figure 1C). | Deletion of McbR is regarded as a key step towards biotechnological L-methionine overproduction in C. glutamicum. | Citation: Deletion of McbR is regarded as a key step towards biotechnological L-methionine overproduction in C. glutamicum. | Deletion of the methionine and cysteine biosynthesis repressor protein (McbR) in Corynebacterium glutamicum to study metabolic consequences. | Citation: In the present work, the metabolic consequences of the deletion of the methionine and cysteine biosynthesis repressor protein (McbR) in Corynebacterium glutamicum, which releases almost all enzymes of methionine biosynthesis and sulfate assimilation from transcriptional regulation (D. A. Rey, A. Puhler, and J. Kalinowski, J. Biotechnol. 103:51-65, 2003), were studied.
A48: asd | B48: Overexpression | C48: L-lysine | D48: 10.1016/j.bej.2020.107665 | E48: TRUE | F48: =IFERROR(VLOOKUP(A48,Sheet1!A:A,1,0),0) -> asd | G48: ASAD: aspsa_c + nadp_c + pi_c <=> 4pasp_c + h_c + nadph_c
A49: metD | B49: Inactivation | C49: L-lysine | D49: 10.1016/j.bej.2020.107665 | E49: FALSE | F49: =IFERROR(VLOOKUP(A49,Sheet1!A:A,1,0),0) -> 0 | G49: Deletion of the metD gene to achieve extracellular accumulation of methionine. | Citation: First, the metD gene encoding the methionine uptake system was deleted to achieve extracellular accumulation of methionine. | Deletion of metD to construct a strain exhibiting high-level production of L-homoserine. | Citation: In the present study, we deleted thrB, mcbR, and metD to construct a strain exhibiting high-level production of L-homoserine.
A50: icd | B50: Inactivation | C50: L-lysine | D50: 10.1128/aem.01942-09 | E50: TRUE | F50: =IFERROR(VLOOKUP(A50,Sheet1!A:A,1,0),0) -> 0 | G50: ICDHyr: icit_c + nadp_c --> akg_c + co2_c + nadph_c
A51: amn | B51: Inactivation | C51: L-lysine | D51: 10.1016/j.biortech.2023.129701 | E51: TRUE | F51: =IFERROR(VLOOKUP(A51,Sheet1!A:A,1,0),0) -> 0 | G51: AMPN: amp_c + h2o_c --> ade_c + r5p_c
A52: lysO | B52: Introduction | C52: L-lysine | D52: 10.1021/acssynbio.1c00492 | E52: FALSE | F52: =IFERROR(VLOOKUP(A52,Sheet1!A:A,1,0),0) -> 0 | G52: Not found in genemapping or cg_modifications
A53: gapN | B53: Overexpression | C53: L-lysine | D53: 10.1016/j.ymben.2021.07.010 | E53: FALSE | F53: =IFERROR(VLOOKUP(A53,Sheet1!A:A,1,0),0) -> 0 | G53: Not found in genemapping or cg_modifications
A54: lysE | B54: Overexpression | C54: L-lysine | D54: 10.3389/fmicb.2021.718511 | E54: FALSE | F54: =IFERROR(VLOOKUP(A54,Sheet1!A:A,1,0),0) -> 0 | G54: Overexpression of lysine decarboxylases to enhance diaminopentane production | Citation: Through overexpression of lysine decarboxylases, successfully diaminopentane production was demonstrated in Corynebacterium glutamicum [1] and Escherichia coli [3]. | Deletion of lysE to increase L-PA production by preventing L-lysine export | Citation: Here, we showed that precluding export of L-lysine by deletion of lysE led to the production of L-PA as major product without concomitant L-lysine formation. | Deletion of the L-lysine exporter lysE to prevent L-lysine secretion into the broth | Citation: To prevent L-lysine secretion into the broth in later ectoine producers, this export was eliminated by the deletion of the L-lysine exporter lysE. | Expression of the ectoine biosynthesis operon ectABCD from Pseudomonas stutzeri in an L-lysine-producing strain and disrupting genes encoding diaminopimelate dehydrogenase and the L-lysine exporter resulted in ectoine production 4.5 g/l. | Citation: Expression of the ectoine biosynthesis operon ectABCD from Pseudomonas stutzeri in an L-lysine-producing strain and disrupting genes encoding diaminopimelate dehydrogenase and the L-lysine exporter resulted in ectoine production 4.5 g/l. | Deletion of lysEG operon to study its effect on L-arginine production | Citation: First, the lysEG operon was deleted in the arginine-producing strain ARG2 since LysE is the major export permease for L-arginine. | Overexpression of lysE to improve L-citrulline production | Citation: Notably, overexpression of lysE in ARG2ΔcgmOpΔlysEG increased the L-citrulline titer from about 8 to about 17 mM. | The expression intensity of lysE was fine-tuned with PdapA-N of different intensity to reduce the content of by-product Lys. | Citation: In addition, the expression intensity of lysE was fine-tuned with PdapA-N of different intensity to reduce the content of by-product Lys. | Inactivation of lysE to reduce conversion of glutamate to arginine | Citation: Transcriptional and fermentation data confirmed that inactivation of lysE E and p putP reduced the conversion of glutamate to arginine and proline, which also contribute to ALA production. | Chromosomal deletion of the lysine exporter gene (lysE) | Citation: 2) chromosomal deletion of the lysine exporter gene (lysE); | Overexpression of LysE promoted the production of L-ornithine. | Citation: Overexpression of LysE was observed to increase L-ornithine production in engineered Corynebacterium glutamicum S9114. | Insertion of a strong promoter P tac upstream of lysE to enhance its expression. | Citation: P tac, a strong promoter, was inserted in the upstream region of lysE on the chromosome. | Additional deletion of lysE further improved l-threonine production by 28% | Citation: deletion of ddh improved l-threonine production by 17%, and additional deletion of lysE further improved l-threonine production by 28%; | Deletion of lysE to avoid L-lysine export | Citation: Introduction of the amino acid exchange T311I in the lysC gene led to feedback-resistant aspartokinase and deletion of lysE avoided L-lysine export. | The deletion of lysE was performed in the diaminopentane-producer C. glutamicum DAP-3c to eliminate secretion of lysine. | Citation: The deletion of lysE was performed in the diaminopentane-producer C. glutamicum DAP-3c to eliminate secretion of lysine. | Deletion of lysine exporter to prevent potential loss of carbon | Citation: DAP-15 DAP-14þdeletion of lysE, encoding the lysine exporter (ΔlysE) | Deleting gene lysE encoding lysine-specific exporter to reduce lysine accumulation and increase threonine and isoleucine production. | Citation: Recombinant C. glutamicum producing Thr and Ile with little lysine accumulation was obtained by deleting gene ddh encoding diaminopimelate dehydrogenase and lysE encoding lysine-specific exporter. | Improve histidine export by introducing lysE from C. glutamicum | Citation: To test the hypothesis that LysE acts as part of a histidine export system, the lysE E gene from C. glutamicum and its homologous gene a argO in E E. coli were separately integrated into the y yjiT T locus of HW5-1 under the control of the trc-promoter, generating strains of HW6-3 and HW6-4. | Eliminating the lysine transporter protein lysE to limit lysine production | Citation: eliminating the lysine transporter protein lysE to limit lysine production | A lysine-ON riboswitch was integrated into the lysE gene to upregulate its expression in response to lysine concentration. | Citation: Selected lysine-ON riboswitches were introduced into the lysE gene (encoding a lysine transport protein) of Corynebacterium glutamicum and used to achieve dynamic control of lysine transport in a recombinant lysine-producing strain, C. glutamicum LPECRS. | Replacement of the lysine efflux permease (lysE) gene with a lysine decarboxylase (cadA) gene | Citation: The effect of replacing the lysine efflux permease (lysE) gene in C. glutamicum with a lysine decarboxylase (cadA) gene from E. coli was also investigated. | The gene encoding L-lysine exporter was deleted to reduce the excretion of L-lysine into the medium and consequently secure more L-lysine for subsequent conversion to glutaric acid. | Citation: Furthermore, the lysE gene encoding an L-lysine exporter was deleted to reduce the excretion of L-lysine into the medium and consequently secure more L-lysine for subsequent conversion to glutaric acid. | Subsequent inactivation of the L-lysine exporter prevented the undesired excretion of lysine while ectoine was still exported. | Citation: Subsequent inactivation of the L-lysine exporter prevented the undesired excretion of lysine while ectoine was still exported. | Deletion of the lysE gene, encoding the l-lysine exporter, to eliminate by-product formation | Citation: The issue of by-product formation was then addressed by deletion of the lysE gene, encoding the l-lysine exporter. | Overexpression of lysE to improve L-ornithine production | Citation: In previous study, we developed an engineered strain of C. glutamicum S9114 by deletion of argF, ncgl1221, argR, and putP, attenuation of odhA, proB, and ncgl2228, and overexpression of lysE, gdh, and argCJBD, which produced up to 25 g/L of ʟ-ornithine in a shake fask culture [14 , 15]. | Overexpression of LysE to enhance l-ornithine production | Citation: Plasmid-based overexpression of argCJBD operon and lysine/arginine transport protein LysE was tested to strengthen l -ornithine synthesis and transportation. | Expression of lysE24 and dapA24 to avoid feedback inhibition and increase L-lysine production. | Citation: From the standpoint of avoiding feedback inhibition, we reported an increase in L-lysine production due to the introduction of dapA24, which encodes a dihydrodipocolinate synthase desensitized to feedback inhibition by L-lysine, in combination with lysE24, a mutated lysE gene originating from Corynebacterium glutamicum 2256. | Overexpression of lysE can increase lysine production by enhancing excretion of lysine | Citation: One target gene lysE encodes a lysine efflux protein and overexpression of lysE can increase lysine production by enhancing excretion of lysine (Zhou and Zeng, 2015).
A55: glpX | B55: Overexpression | C55: L-lysine | D55: 10.1128/aem.71.12.8587-8596.2005 | E55: TRUE | F55: =IFERROR(VLOOKUP(A55,Sheet1!A:A,1,0),0) -> 0 | G55: FBP: fdp_c + h2o_c --> f6p_c + pi_c
A56: gapX | B56: Overexpression | C56: L-lysine | D56: 10.1016/j.jbiotec.2012.07.190 | E56: FALSE | F56: =IFERROR(VLOOKUP(A56,Sheet1!A:A,1,0),0) -> 0 | G56: Overexpression of glyceraldehyde 3-phosphate dehydrogenase to enhance lysine production. | Citation: Overexpression of the genes fbp and gapX in C. glutamicum was achieved by cloning the open reading frame (ORF) of the mentioned genes under the control of the strong constitutive promoter of the sod gene, encoding superoxide dismutase (NCgl2826).
A57: dapB | B57: Overexpression | C57: L-lysine | D57: 10.1128/aem.01942-09 | E57: TRUE | F57: =IFERROR(VLOOKUP(A57,Sheet1!A:A,1,0),0) -> dapB | G57: DHDPRy: 23dhdp_c + h_c + nadph_c --> nadp_c + thdp_c
A58: sucC | B58: Inactivation | C58: L-lysine | D58: 10.1016/j.ymben.2012.07.005 | E58: TRUE | F58: =IFERROR(VLOOKUP(A58,Sheet1!A:A,1,0),0) -> 0 | G58: SUCOAS: adp_c + pi_c + succoa_c --> atp_c + coa_c + succ_c
... A80: sigH | B80: Inactivation | C80: L-lysine | D80: 10.1186/s12934-020-1294-7 | E80: FALSE | F80: =IFERROR(VLOOKUP(A80,Sheet1!A:A,1,0),0) -> 0 | G80: Deletion of the sigH gene decreases the accumulation of by-products in C. glutamicum strain | Citation: In order to increase the expression level of FOF1-ATPase-coding gene at neutral pH, we deleted SigH-coding gene sigH to construct a SigH-deficient strain C. glutamicum K-8.
A81: ilvA | B81: Inactivation | C81: L-valine | D81: 10.1128/AEM.69.5.2521-2532.2003 | E81: TRUE | G81: THRD_L: thr__L_c --> 2obut_c + nh4_c
A82: lrp | B82: Overexpression | C82: L-valine | D82: 10.1073/pnas.0702609104 | E82: FALSE | G82: Not found in genemapping or cg_modifications
A83: aceF | B83: Inactivation | C83: L-valine | D83: 10.1002/bit.22995 | E83: TRUE | G83: PDH: coa_c + nad_c + pyr_c --> accoa_c + co2_c + nadh_c
A84: mdh | B84: Overexpression | C84: L-valine | D84: 10.1002/bit.22995 | E84: TRUE | G84: MDH: mal__L_c + nad_c <=> h_c + nadh_c + oaa_c
A85: pfkA | B85: Inactivation | C85: L-valine | D85: 10.1002/bit.22995 | E85: TRUE | G85: PFK_2: atp_c + tag6p__D_c --> adp_c + h_c + tagdp__D_c, PFK: atp_c + f6p_c --> adp_c + fdp_c + h_c, PFK_3
A86: leuD | B86: Inactivation | C86: L-valine | D86: 10.1016/j.plasmid.2014.07.005 | E86: TRUE | G86: IPPMIa: 3c2hmp_c <=> 2ippm_c + h2o_c, IPPMIb: 2ippm_c + h2o_c <=> 3c3hmp_c
A87: lysC | B87: Inactivation | C87: L-valine | D87: 10.1007/s10295-016-1763-5 | E87: TRUE | G87: ASPK: asp__L_c + atp_c <=> 4pasp_c + adp_c
